2025-02-24 20:09:48,108:DEBUG:certbot._internal.main:certbot version: 2.10.0
2025-02-24 20:09:48,109:DEBUG:certbot._internal.main:Location of certbot entry point: /usr/bin/certbot
2025-02-24 20:09:48,109:DEBUG:certbot._internal.main:Arguments: ['-v', '--webroot', '--agree-tos', '--renew-by-default', '--preferred-challenges', 'http-01', '--email', 'vaxelaire.yohem@gmail.com', '--webroot-path', '/var/www/certbot', '--cert-name', 'minepiece.fr', '-d', 'minepiece.fr', '-d', 'www.minepiece.fr']
2025-02-24 20:09:48,109:DEBUG:certbot._internal.main:Discovered plugins: PluginsRegistry(PluginEntryPoint#manual,PluginEntryPoint#null,PluginEntryPoint#standalone,PluginEntryPoint#webroot)
2025-02-24 20:09:48,151:DEBUG:certbot._internal.log:Root logging level set at 20
2025-02-24 20:09:48,152:DEBUG:certbot._internal.plugins.selection:Requested authenticator webroot and installer None
2025-02-24 20:09:48,152:DEBUG:certbot._internal.plugins.selection:Single candidate plugin: * webroot
Description: Saves the necessary validation files to a .well-known/acme-challenge/ directory within the nominated webroot path. A seperate HTTP server must be running and serving files from the webroot path. HTTP challenge only (wildcards not supported).
Interfaces: Authenticator, Plugin
Entry point: EntryPoint(name='webroot', value='certbot._internal.plugins.webroot:Authenticator', group='certbot.plugins')
Initialized: <certbot._internal.plugins.webroot.Authenticator object at 0x7f687e1ae6f0>
Prep: True
2025-02-24 20:09:48,152:DEBUG:certbot._internal.plugins.selection:Selected authenticator <certbot._internal.plugins.webroot.Authenticator object at 0x7f687e1ae6f0> and installer None
2025-02-24 20:09:48,152:INFO:certbot._internal.plugins.selection:Plugins selected: Authenticator webroot, Installer None
2025-02-24 20:09:48,201:DEBUG:certbot._internal.main:Picked account: <Account(RegistrationResource(body=Registration(key=None, contact=(), agreement=None, status=None, terms_of_service_agreed=None, only_return_existing=None, external_account_binding=None), uri='https://acme-v02.api.letsencrypt.org/acme/acct/2243553505', new_authzr_uri=None, terms_of_service=None), b674a225a17192af95a621d2ec1bc036, Meta(creation_dt=datetime.datetime(2025, 2, 22, 10, 55, 38, tzinfo=<UTC>), creation_host='faa0276bdd8e', register_to_eff=None))>
2025-02-24 20:09:48,201:DEBUG:acme.client:Sending GET request to https://acme-v02.api.letsencrypt.org/directory.
2025-02-24 20:09:48,203:DEBUG:urllib3.connectionpool:Starting new HTTPS connection (1): acme-v02.api.letsencrypt.org:443
2025-02-24 20:09:48,568:DEBUG:urllib3.connectionpool:https://acme-v02.api.letsencrypt.org:443 "GET /directory HTTP/1.1" 200 1042
2025-02-24 20:09:48,569:DEBUG:acme.client:Received response:
HTTP 200
Server: nginx
Date: Mon, 24 Feb 2025 20:09:48 GMT
Content-Type: application/json
Content-Length: 1042
Connection: keep-alive
Cache-Control: public, max-age=0, no-cache
X-Frame-Options: DENY
Strict-Transport-Security: max-age=604800

{
  "keyChange": "https://acme-v02.api.letsencrypt.org/acme/key-change",
  "meta": {
    "caaIdentities": [
      "letsencrypt.org"
    ],
    "profiles": {
      "classic": "https://letsencrypt.org/docs/profiles#classic",
      "shortlived": "https://letsencrypt.org/docs/profiles#shortlived (not yet generally available)",
      "tlsserver": "https://letsencrypt.org/docs/profiles#tlsserver (not yet generally available)"
    },
    "termsOfService": "https://letsencrypt.org/documents/LE-SA-v1.5-February-24-2025.pdf",
    "website": "https://letsencrypt.org"
  },
  "newAccount": "https://acme-v02.api.letsencrypt.org/acme/new-acct",
  "newNonce": "https://acme-v02.api.letsencrypt.org/acme/new-nonce",
  "newOrder": "https://acme-v02.api.letsencrypt.org/acme/new-order",
  "renewalInfo": "https://acme-v02.api.letsencrypt.org/draft-ietf-acme-ari-03/renewalInfo",
  "revokeCert": "https://acme-v02.api.letsencrypt.org/acme/revoke-cert",
  "tUsa9g6lNKo": "https://community.letsencrypt.org/t/adding-random-entries-to-the-directory/33417"
}
2025-02-24 20:09:48,574:DEBUG:certbot._internal.renewal:Auto-renewal forced with --force-renewal...
2025-02-24 20:09:48,574:DEBUG:certbot._internal.display.obj:Notifying user: Renewing an existing certificate for minepiece.fr and www.minepiece.fr
2025-02-24 20:09:48,576:DEBUG:acme.client:Requesting fresh nonce
2025-02-24 20:09:48,576:DEBUG:acme.client:Sending HEAD request to https://acme-v02.api.letsencrypt.org/acme/new-nonce.
2025-02-24 20:09:48,697:DEBUG:urllib3.connectionpool:https://acme-v02.api.letsencrypt.org:443 "HEAD /acme/new-nonce HTTP/1.1" 200 0
2025-02-24 20:09:48,698:DEBUG:acme.client:Received response:
HTTP 200
Server: nginx
Date: Mon, 24 Feb 2025 20:09:48 GMT
Connection: keep-alive
Cache-Control: public, max-age=0, no-cache
Link: <https://acme-v02.api.letsencrypt.org/directory>;rel="index"
Replay-Nonce: ozgn15WX21_AMxn5myXP6lFAMBbDJLn_eQvu34eC-_0PrShdJQo
X-Frame-Options: DENY
Strict-Transport-Security: max-age=604800


2025-02-24 20:09:48,698:DEBUG:acme.client:Storing nonce: ozgn15WX21_AMxn5myXP6lFAMBbDJLn_eQvu34eC-_0PrShdJQo
2025-02-24 20:09:48,698:DEBUG:acme.client:JWS payload:
b'{\n  "identifiers": [\n    {\n      "type": "dns",\n      "value": "minepiece.fr"\n    },\n    {\n      "type": "dns",\n      "value": "www.minepiece.fr"\n    }\n  ]\n}'
2025-02-24 20:09:48,700:DEBUG:acme.client:Sending POST request to https://acme-v02.api.letsencrypt.org/acme/new-order:
{
  "protected": "eyJhbGciOiAiUlMyNTYiLCAia2lkIjogImh0dHBzOi8vYWNtZS12MDIuYXBpLmxldHNlbmNyeXB0Lm9yZy9hY21lL2FjY3QvMjI0MzU1MzUwNSIsICJub25jZSI6ICJvemduMTVXWDIxX0FNeG41bXlYUDZsRkFNQmJESkxuX2VRdnUzNGVDLV8wUHJTaGRKUW8iLCAidXJsIjogImh0dHBzOi8vYWNtZS12MDIuYXBpLmxldHNlbmNyeXB0Lm9yZy9hY21lL25ldy1vcmRlciJ9",
  "signature": "RHNHDT0jQKDI81oKbmPWcBX25kHx8x5Asv6O6dwWGOSNJstnFC3DldhjyKflm2qvNeGWH7jZy3zKIW5jkZfJShLkcdYCX1KfUV-zuZN1e_gAu_jSfDwg95c025i7FTtkHMyTmlpTPVaE8ws0wnoAVf75WnYOBgd2Ed1IEXUx10HNQ7BBX6JP185a9AS-JTkNS1JB3fRFO-pZWPl5OLHDxf_52Zb7A60m7retx3jpYsU0RHpUUiJWW74rMmOcIKociFxMvYPRpquJkEukXXsvNebOT9YnyKtfNMvTaZg9FjsTLgU8p5uISO7P4CgMuW1MMPDzBVnR3fRh0dS-mffVHQ",
  "payload": "ewogICJpZGVudGlmaWVycyI6IFsKICAgIHsKICAgICAgInR5cGUiOiAiZG5zIiwKICAgICAgInZhbHVlIjogIm1pbmVwaWVjZS5mciIKICAgIH0sCiAgICB7CiAgICAgICJ0eXBlIjogImRucyIsCiAgICAgICJ2YWx1ZSI6ICJ3d3cubWluZXBpZWNlLmZyIgogICAgfQogIF0KfQ"
}
2025-02-24 20:09:48,844:DEBUG:urllib3.connectionpool:https://acme-v02.api.letsencrypt.org:443 "POST /acme/new-order HTTP/1.1" 429 306
2025-02-24 20:09:48,845:DEBUG:acme.client:Received response:
HTTP 429
Server: nginx
Date: Mon, 24 Feb 2025 20:09:48 GMT
Content-Type: application/problem+json
Content-Length: 306
Connection: keep-alive
Boulder-Requester: 2243553505
Cache-Control: public, max-age=0, no-cache
Link: <https://acme-v02.api.letsencrypt.org/directory>;rel="index", <https://letsencrypt.org/docs/rate-limits>;rel="help"
Replay-Nonce: ozgn15WXB_c2uyyfGNxARHQzKrGUBJ_3n8DKFVt7vIEt18um6mM
Retry-After: 50186

{
  "type": "urn:ietf:params:acme:error:rateLimited",
  "detail": "too many certificates (5) already issued for this exact set of domains in the last 168h0m0s, retry after 2025-02-25 10:06:14 UTC: see https://letsencrypt.org/docs/rate-limits/#new-certificates-per-exact-set-of-hostnames",
  "status": 429
}
2025-02-24 20:09:48,845:DEBUG:certbot._internal.log:Exiting abnormally:
Traceback (most recent call last):
  File "/usr/bin/certbot", line 8, in <module>
    sys.exit(main())
             ^^^^^^
  File "/usr/lib/python3.12/site-packages/certbot/main.py", line 19, in main
    return internal_main.main(cli_args)
           ^^^^^^^^^^^^^^^^^^^^^^^^^^^^
  File "/usr/lib/python3.12/site-packages/certbot/_internal/main.py", line 1894, in main
    return config.func(config, plugins)
           ^^^^^^^^^^^^^^^^^^^^^^^^^^^^
  File "/usr/lib/python3.12/site-packages/certbot/_internal/main.py", line 1600, in certonly
    lineage = _get_and_save_cert(le_client, config, domains, certname, lineage)
              ^^^^^^^^^^^^^^^^^^^^^^^^^^^^^^^^^^^^^^^^^^^^^^^^^^^^^^^^^^^^^^^^^
  File "/usr/lib/python3.12/site-packages/certbot/_internal/main.py", line 131, in _get_and_save_cert
    renewal.renew_cert(config, domains, le_client, lineage)
  File "/usr/lib/python3.12/site-packages/certbot/_internal/renewal.py", line 399, in renew_cert
    new_cert, new_chain, new_key, _ = le_client.obtain_certificate(domains, new_key)
                                      ^^^^^^^^^^^^^^^^^^^^^^^^^^^^^^^^^^^^^^^^^^^^^^
  File "/usr/lib/python3.12/site-packages/certbot/_internal/client.py", line 428, in obtain_certificate
    orderr = self._get_order_and_authorizations(csr.data, self.config.allow_subset_of_names)
             ^^^^^^^^^^^^^^^^^^^^^^^^^^^^^^^^^^^^^^^^^^^^^^^^^^^^^^^^^^^^^^^^^^^^^^^^^^^^^^^
  File "/usr/lib/python3.12/site-packages/certbot/_internal/client.py", line 478, in _get_order_and_authorizations
    orderr = self.acme.new_order(csr_pem)
             ^^^^^^^^^^^^^^^^^^^^^^^^^^^^
  File "/usr/lib/python3.12/site-packages/acme/client.py", line 137, in new_order
    response = self._post(self.directory['newOrder'], order)
               ^^^^^^^^^^^^^^^^^^^^^^^^^^^^^^^^^^^^^^^^^^^^^
  File "/usr/lib/python3.12/site-packages/acme/client.py", line 365, in _post
    return self.net.post(*args, **kwargs)
           ^^^^^^^^^^^^^^^^^^^^^^^^^^^^^^
  File "/usr/lib/python3.12/site-packages/acme/client.py", line 738, in post
    return self._post_once(*args, **kwargs)
           ^^^^^^^^^^^^^^^^^^^^^^^^^^^^^^^^
  File "/usr/lib/python3.12/site-packages/acme/client.py", line 751, in _post_once
    response = self._check_response(response, content_type=content_type)
               ^^^^^^^^^^^^^^^^^^^^^^^^^^^^^^^^^^^^^^^^^^^^^^^^^^^^^^^^^
  File "/usr/lib/python3.12/site-packages/acme/client.py", line 602, in _check_response
    raise messages.Error.from_json(jobj)
acme.messages.Error: urn:ietf:params:acme:error:rateLimited :: There were too many requests of a given type :: too many certificates (5) already issued for this exact set of domains in the last 168h0m0s, retry after 2025-02-25 10:06:14 UTC: see https://letsencrypt.org/docs/rate-limits/#new-certificates-per-exact-set-of-hostnames
2025-02-24 20:09:48,849:ERROR:certbot._internal.log:An unexpected error occurred:
2025-02-24 20:09:48,849:ERROR:certbot._internal.log:too many certificates (5) already issued for this exact set of domains in the last 168h0m0s, retry after 2025-02-25 10:06:14 UTC: see https://letsencrypt.org/docs/rate-limits/#new-certificates-per-exact-set-of-hostnames
